Workbook

Sheet CENTRO ANDAMENTO ALUNOS
A1: ALUNOS | B1: EDUCADOR | C1: DIA SEMANA | D1: DATA INICIO | E1: DATA TERMINO | F1: TOTAL SEMANAS | G1: SEMANAS CONCLUIDAS | H1: AULAS CURSO | I1: AULAS CONCLUIDAS | J1: AULAS ATRASADAS | K1: SITUAÇÃO | L1: DATA ACOMPANHAMENTO | M1: DIAS VERIFICADOS | N1: VERIFICAÇÃO
A2: ACSA MARIA ALVES DA SILVA | B2: JOICE LOPES | C2: =L2 -> 46163 | D2: 46077 | E2: 46654 | F2: =(E2-D2)/7 -> 82.428571 | G2: =(TODAY()-D2)/7 -> 13.428571 | H2: 80 | I2: 17 | J2: =IFERROR(((G2*H2)/F2)-I2,"") -> -3.9670711 | K2: =IF(J2<-10,"MUITO ADIANTADO",IF(J2<-6,"ADIANTADO",IF(J2<6,"EM DIAS",IF(J2<12,"ATRASADO","MUITO ATRASADO")))) -> EM DIAS | L2: 46163 | M2: =TODAY()-L2 -> 8 | N2: =IF(M2<8,"VERIFICADO",IF(M2<15,"VERIFICAR","VERIFICAR URGENTE")) -> VERIFICAR
A3: ADRIANA DA SILVA SOUZA | B3: NUBIA CARVALHO | C3: =L3 -> 46162 | D3: 46059 | E3: 46394 | F3: =(E3-D3)/7 -> 47.857143 | G3: =(TODAY()-D3)/7 -> 16 | H3: 48 | I3: 12 | J3: =IFERROR(((G3*H3)/F3)-I3,"") -> 4.0477612 | K3: =IF(J3<-10,"MUITO ADIANTADO",IF(J3<-6,"ADIANTADO",IF(J3<6,"EM DIAS",IF(J3<12,"ATRASADO","MUITO ATRASADO")))) -> EM DIAS | L3: 46162 | M3: =TODAY()-L3 -> 9 | N3: =IF(M3<8,"VERIFICADO",IF(M3<15,"VERIFICAR","VERIFICAR URGENTE")) -> VERIFICAR
A4: FERNANDA CHRISÓSTOMO BOMFIM VALADARES | B4: JORGE SOUZA | C4: =L4 -> 46162 | D4: 45790 | E4: 46249 | F4: =(E4-D4)/7 -> 65.571429 | G4: =(TODAY()-D4)/7 -> 54.428571 | H4: 112 | I4: 92 | J4: =IFERROR(((G4*H4)/F4)-I4,"") -> 0.96732026 | K4: =IF(J4<-10,"MUITO ADIANTADO",IF(J4<-6,"ADIANTADO",IF(J4<6,"EM DIAS",IF(J4<12,"ATRASADO","MUITO ATRASADO")))) -> EM DIAS | L4: 46162 | M4: =TODAY()-L4 -> 9 | N4: =IF(M4<8,"VERIFICADO",IF(M4<15,"VERIFICAR","VERIFICAR URGENTE")) -> VERIFICAR
A5: ISABELA CARVALHO BONFIM | B5: JORGE SOUZA | C5: =L5 -> 46162 | D5: 45141 | E5: 46386 | F5: =(E5-D5)/7 -> 177.85714 | G5: =(TODAY()-D5)/7 -> 147.14286 | H5: 192 | I5: 166 | J5: =IFERROR(((G5*H5)/F5)-I5,"") -> -7.1566265 | K5: =IF(J5<-10,"MUITO ADIANTADO",IF(J5<-6,"ADIANTADO",IF(J5<6,"EM DIAS",IF(J5<12,"ATRASADO","MUITO ATRASADO")))) -> ADIANTADO | L5: 46162 | M5: =TODAY()-L5 -> 9 | N5: =IF(M5<8,"VERIFICADO",IF(M5<15,"VERIFICAR","VERIFICAR URGENTE")) -> VERIFICAR
A6: ADRIMY DAMACENO RIBEIRO | B6: EDILEUSA CHAVES | C6: =L6 -> 46163 | D6: 46093 | E6: 47557 | F6: =(E6-D6)/7 -> 209.14286 | G6: =(TODAY()-D6)/7 -> 11.142857 | H6: 208 | I6: 14 | J6: =IFERROR(((G6*H6)/F6)-I6,"") -> -2.9180328 | K6: =IF(J6<-10,"MUITO ADIANTADO",IF(J6<-6,"ADIANTADO",IF(J6<6,"EM DIAS",IF(J6<12,"ATRASADO","MUITO ATRASADO")))) -> EM DIAS | L6: 46163 | M6: =TODAY()-L6 -> 8 | N6: =IF(M6<8,"VERIFICADO",IF(M6<15,"VERIFICAR","VERIFICAR URGENTE")) -> VERIFICAR
A7: ADRYAN PINHEIRO CAMPOS | B7: EDMUNDO SANTOS | C7: =L7 -> 46163 | D7: 45881 | E7: 46578 | F7: =(E7-D7)/7 -> 99.571429 | G7: =(TODAY()-D7)/7 -> 41.428571 | H7: 112 | I7: 40 | J7: =IFERROR(((G7*H7)/F7)-I7,"") -> 6.5997131 | K7: =IF(J7<-10,"MUITO ADIANTADO",IF(J7<-6,"ADIANTADO",IF(J7<6,"EM DIAS",IF(J7<12,"ATRASADO","MUITO ATRASADO")))) -> ATRASADO | L7: 46163 | M7: =TODAY()-L7 -> 8 | N7: =IF(M7<8,"VERIFICADO",IF(M7<15,"VERIFICAR","VERIFICAR URGENTE")) -> VERIFICAR
A8: ADRYANA KELLY RODRIGUES DA SILVA | B8: EDILEUSA CHAVES | C8: =L8 -> 46163 | D8: 46148 | E8: 46822 | F8: =(E8-D8)/7 -> 96.285714 | G8: 0 | H8: 112 | I8: 5 | J8: =IFERROR(((G8*H8)/F8)-I8,"") -> -5 | K8: =IF(J8<-10,"MUITO ADIANTADO",IF(J8<-6,"ADIANTADO",IF(J8<6,"EM DIAS",IF(J8<12,"ATRASADO","MUITO ATRASADO")))) -> EM DIAS | L8: 46163 | M8: =TODAY()-L8 -> 8 | N8: =IF(M8<8,"VERIFICADO",IF(M8<15,"VERIFICAR","VERIFICAR URGENTE")) -> VERIFICAR
A9: AFIA MARIA ALVES DA SILVA | B9: EDILEUSA CHAVES | C9: =L9 -> 46163 | D9: 45811 | E9: 46376 | F9: =(E9-D9)/7 -> 80.714286 | G9: =(TODAY()-D9)/7 -> 51.428571 | H9: 80 | I9: 43 | J9: =IFERROR(((G9*H9)/F9)-I9,"") -> 7.9734513 | K9: =IF(J9<-10,"MUITO ADIANTADO",IF(J9<-6,"ADIANTADO",IF(J9<6,"EM DIAS",IF(J9<12,"ATRASADO","MUITO ATRASADO")))) -> ATRASADO | L9: 46163 | M9: =TODAY()-L9 -> 8 | N9: =IF(M9<8,"VERIFICADO",IF(M9<15,"VERIFICAR","VERIFICAR URGENTE")) -> VERIFICAR
A10: ALAIANA DE OLIVEIRA ESTEVAM | B10: EDILEUSA CHAVES | C10: =L10 -> 46161 | D10: 45947 | E10: 46407 | F10: =(E10-D10)/7 -> 65.714286 | G10: =(TODAY()-D10)/7 -> 32 | H10: 80 | I10: 41 | J10: =IFERROR(((G10*H10)/F10)-I10,"") -> -2.0434783 | K10: =IF(J10<-10,"MUITO ADIANTADO",IF(J10<-6,"ADIANTADO",IF(J10<6,"EM DIAS",IF(J10<12,"ATRASADO","MUITO ATRASADO")))) -> EM DIAS | L10: 46161 | M10: =TODAY()-L10 -> 10 | N10: =IF(M10<8,"VERIFICADO",IF(M10<15,"VERIFICAR","VERIFICAR URGENTE")) -> VERIFICAR
A11: ALANA ARAUJO COSTA | B11: NUBIA CARVALHO | C11: =L11 -> 46157 | D11: 45933 | E11: 46325 | F11: =(E11-D11)/7 -> 56 | G11: =(TODAY()-D11)/7 -> 34 | H11: 64 | I11: 35 | J11: =IFERROR(((G11*H11)/F11)-I11,"") -> 3.8571429 | K11: =IF(J11<-10,"MUITO ADIANTADO",IF(J11<-6,"ADIANTADO",IF(J11<6,"EM DIAS",IF(J11<12,"ATRASADO","MUITO ATRASADO")))) -> EM DIAS | L11: 46157 | M11: =TODAY()-L11 -> 14 | N11: =IF(M11<8,"VERIFICADO",IF(M11<15,"VERIFICAR","VERIFICAR URGENTE")) -> VERIFICAR
A12: ALANA ÉVANI DOS SANTOS SILVA | B12: EDILEUSA CHAVES | C12: =L12 -> 46165 | D12: 45875 | E12: 47609 | F12: =(E12-D12)/7 -> 247.71429 | G12: =(TODAY()-D12)/7 -> 42.285714 | H12: 257 | I12: 40 | J12: =IFERROR(((G12*H12)/F12)-I12,"") -> 3.8708189 | K12: =IF(J12<-10,"MUITO ADIANTADO",IF(J12<-6,"ADIANTADO",IF(J12<6,"EM DIAS",IF(J12<12,"ATRASADO","MUITO ATRASADO")))) -> EM DIAS | L12: 46165 | M12: =TODAY()-L12 -> 6 | N12: =IF(M12<8,"VERIFICADO",IF(M12<15,"VERIFICAR","VERIFICAR URGENTE")) -> VERIFICADO
A13: DORAN DOS SANTOS SILVA | B13: JORGE SOUZA | C13: =L13 -> 46162 | D13: 45889 | E13: 46822 | F13: =(E13-D13)/7 -> 133.28571 | G13: =(TODAY()-D13)/7 -> 40.285714 | H13: 128 | I13: 38 | J13: =IFERROR(((G13*H13)/F13)-I13,"") -> 0.68810289 | K13: =IF(J13<-10,"MUITO ADIANTADO",IF(J13<-6,"ADIANTADO",IF(J13<6,"EM DIAS",IF(J13<12,"ATRASADO","MUITO ATRASADO")))) -> EM DIAS | L13: 46162 | M13: =TODAY()-L13 -> 9 | N13: =IF(M13<8,"VERIFICADO",IF(M13<15,"VERIFICAR","VERIFICAR URGENTE")) -> VERIFICAR
A14: ALEXANDRE LEAL NASCIMENTO | B14: EDILEUSA CHAVES | C14: =L14 -> 46163 | D14: 45890 | E14: 46784 | F14: =(E14-D14)/7 -> 127.71429 | G14: =(TODAY()-D14)/7 -> 40.142857 | H14: 160 | I14: 55 | J14: =IFERROR(((G14*H14)/F14)-I14,"") -> -4.7091723 | K14: =IF(J14<-10,"MUITO ADIANTADO",IF(J14<-6,"ADIANTADO",IF(J14<6,"EM DIAS",IF(J14<12,"ATRASADO","MUITO ATRASADO")))) -> EM DIAS | L14: 46163 | M14: =TODAY()-L14 -> 8 | N14: =IF(M14<8,"VERIFICADO",IF(M14<15,"VERIFICAR","VERIFICAR URGENTE")) -> VERIFICAR
A15: ALICE DE SOUZA SCHMIDT | B15: JOICE LOPES | C15: =L15 -> 46164 | D15: 45750 | E15: 46296 | F15: =(E15-D15)/7 -> 78 | G15: =(TODAY()-D15)/7 -> 60.142857 | H15: 80 | I15: 58 | J15: =IFERROR(((G15*H15)/F15)-I15,"") -> 3.6849817 | K15: =IF(J15<-10,"MUITO ADIANTADO",IF(J15<-6,"ADIANTADO",IF(J15<6,"EM DIAS",IF(J15<12,"ATRASADO","MUITO ATRASADO")))) -> EM DIAS | L15: 46164 | M15: =TODAY()-L15 -> 7 | N15: =IF(M15<8,"VERIFICADO",IF(M15<15,"VERIFICAR","VERIFICAR URGENTE")) -> VERIFICADO
A16: ALICE GOMES OLIVEIRA | B16: JOICE LOPES | C16: =L16 -> 46161 | D16: 45986 | E16: 46537 | F16: =(E16-D16)/7 -> 78.714286 | G16: =(TODAY()-D16)/7 -> 26.428571 | H16: 80 | I16: 25 | J16: =IFERROR(((G16*H16)/F16)-I16,"") -> 1.8602541 | K16: =IF(J16<-10,"MUITO ADIANTADO",IF(J16<-6,"ADIANTADO",IF(J16<6,"EM DIAS",IF(J16<12,"ATRASADO","MUITO ATRASADO")))) -> EM DIAS | L16: 46161 | M16: =TODAY()-L16 -> 10 | N16: =IF(M16<8,"VERIFICADO",IF(M16<15,"VERIFICAR","VERIFICAR URGENTE")) -> VERIFICAR
A17: ALICE NOVAIS BONFIM | B17: EDILEUSA CHAVES | C17: =L17 -> 46163 | D17: 45967 | E17: 46532 | F17: =(E17-D17)/7 -> 80.714286 | G17: =(TODAY()-D17)/7 -> 29.142857 | H17: 80 | I17: 30 | J17: =IFERROR(((G17*H17)/F17)-I17,"") -> -1.1150442 | K17: =IF(J17<-10,"MUITO ADIANTADO",IF(J17<-6,"ADIANTADO",IF(J17<6,"EM DIAS",IF(J17<12,"ATRASADO","MUITO ATRASADO")))) -> EM DIAS | L17: 46163 | M17: =TODAY()-L17 -> 8 | N17: =IF(M17<8,"VERIFICADO",IF(M17<15,"VERIFICAR","VERIFICAR URGENTE")) -> VERIFICAR
A18: ISABELLA ALVES SILVA OLIVEIRA | B18: EDILEUSA CHAVES | C18: =L18 -> 46161 | D18: 45853 | E18: 46419 | F18: =(E18-D18)/7 -> 80.857143 | G18: =(TODAY()-D18)/7 -> 45.428571 | H18: 80 | I18: 41 | J18: =IFERROR(((G18*H18)/F18)-I18,"") -> 3.9469965 | K18: =IF(J18<-10,"MUITO ADIANTADO",IF(J18<-6,"ADIANTADO",IF(J18<6,"EM DIAS",IF(J18<12,"ATRASADO","MUITO ATRASADO")))) -> EM DIAS | L18: 46161 | M18: =TODAY()-L18 -> 10 | N18: =IF(M18<8,"VERIFICADO",IF(M18<15,"VERIFICAR","VERIFICAR URGENTE")) -> VERIFICAR
A19: AMANDA NOLASCO BARROS | B19: JORGE SOUZA | C19: =L19 -> 46162 | D19: 45409 | E19: 46172 | F19: =(E19-D19)/7 -> 109 | G19: =(TODAY()-D19)/7 -> 108.85714 | H19: 128 | I19: 124 | J19: =IFERROR(((G19*H19)/F19)-I19,"") -> 3.8322412 | K19: =IF(J19<-10,"MUITO ADIANTADO",IF(J19<-6,"ADIANTADO",IF(J19<6,"EM DIAS",IF(J19<12,"ATRASADO","MUITO ATRASADO")))) -> EM DIAS | L19: 46162 | M19: =TODAY()-L19 -> 9 | N19: =IF(M19<8,"VERIFICADO",IF(M19<15,"VERIFICAR","VERIFICAR URGENTE")) -> VERIFICAR
A20: ALLISON ALVES PEREIRA DA SILVA | B20: EDMUNDO SANTOS | C20: =L20 -> 46158 | D20: 46123 | E20: 46485 | F20: =(E20-D20)/7 -> 51.714286 | G20: =(TODAY()-D20)/7 -> 6.8571429 | H20: 80 | I20: 9 | J20: =IFERROR(((G20*H20)/F20)-I20,"") -> 1.6077348 | K20: =IF(J20<-10,"MUITO ADIANTADO",IF(J20<-6,"ADIANTADO",IF(J20<6,"EM DIAS",IF(J20<12,"ATRASADO","MUITO ATRASADO")))) -> EM DIAS | L20: 46158 | M20: =TODAY()-L20 -> 13 | N20: =IF(M20<8,"VERIFICADO",IF(M20<15,"VERIFICAR","VERIFICAR URGENTE")) -> VERIFICAR
... A42: ANA LUIZA RIBEIRO DISCONZI | B42: EDMUNDO SANTOS | C42: =L42 -> 46158 | D42: 45951 | E42: 46423 | F42: =(E42-D42)/7 -> 67.428571 | G42: =(TODAY()-D42)/7 -> 31.428571 | H42: 64 | I42: 32 | J42: =IFERROR(((G42*H42)/F42)-I42,"") -> -2.1694915 | K42: =IF(J42<-10,"MUITO ADIANTADO",IF(J42<-6,"ADIANTADO",IF(J42<6,"EM DIAS",IF(J42<12,"ATRASADO","MUITO ATRASADO")))) -> EM DIAS | L42: 46158 | M42: =TODAY()-L42 -> 13 | N42: =IF(M42<8,"VERIFICADO",IF(M42<15,"VERIFICAR","VERIFICAR URGENTE")) -> VERIFICAR
A43: ANA RAFAELA DE ALMEIDA PENA | B43: JOICE LOPES | C43: =L43 -> 46161 | D43: 46119 | E43: 46246 | F43: =(E43-D43)/7 -> 18.142857 | G43: 0 | H43: 16 | I43: 6 | J43: =IFERROR(((G43*H43)/F43)-I43,"") -> -6 | K43: =IF(J43<-10,"MUITO ADIANTADO",IF(J43<-6,"ADIANTADO",IF(J43<6,"EM DIAS",IF(J43<12,"ATRASADO","MUITO ATRASADO")))) -> EM DIAS | L43: 46161 | M43: =TODAY()-L43 -> 10 | N43: =IF(M43<8,"VERIFICADO",IF(M43<15,"VERIFICAR","VERIFICAR URGENTE")) -> VERIFICAR
A44: ANA SOPHIA FERREIRA DE SOUZA | B44: EDILEUSA CHAVES | C44: =L44 -> 46163 | D44: 45882 | E44: 46598 | F44: =(E44-D44)/7 -> 102.28571 | G44: =(TODAY()-D44)/7 -> 41.285714 | H44: 112 | I44: 39 | J44: =IFERROR(((G44*H44)/F44)-I44,"") -> 6.2067039 | K44: =IF(J44<-10,"MUITO ADIANTADO",IF(J44<-6,"ADIANTADO",IF(J44<6,"EM DIAS",IF(J44<12,"ATRASADO","MUITO ATRASADO")))) -> ATRASADO | L44: 46163 | M44: =TODAY()-L44 -> 8 | N44: =IF(M44<8,"VERIFICADO",IF(M44<15,"VERIFICAR","VERIFICAR URGENTE")) -> VERIFICAR
A45: ANA SOPHIA RODRIGUES DE MIRANDA | B45: EDMUNDO SANTOS | C45: =L45 -> 46164 | D45: 46001 | E45: 46564 | F45: =(E45-D45)/7 -> 80.428571 | G45: =(TODAY()-D45)/7 -> 24.285714 | H45: 80 | I45: 13 | J45: =IFERROR(((G45*H45)/F45)-I45,"") -> 11.156306 | K45: =IF(J45<-10,"MUITO ADIANTADO",IF(J45<-6,"ADIANTADO",IF(J45<6,"EM DIAS",IF(J45<12,"ATRASADO","MUITO ATRASADO")))) -> ATRASADO | L45: 46164 | M45: =TODAY()-L45 -> 7 | N45: =IF(M45<8,"VERIFICADO",IF(M45<15,"VERIFICAR","VERIFICAR URGENTE")) -> VERIFICADO
A46: ANA VALÉRIA PEREIRA LIMA | B46: TANIA ANJOS | C46: =L46 -> 46177 | D46: 46135 | E46: 46524 | F46: =(E46-D46)/7 -> 55.571429 | G46: =(TODAY()-D46)/7 -> 5.1428571 | H46: 100 | I46: 5 | J46: =IFERROR(((G46*H46)/F46)-I46,"") -> 4.2544987 | K46: =IF(J46<-10,"MUITO ADIANTADO",IF(J46<-6,"ADIANTADO",IF(J46<6,"EM DIAS",IF(J46<12,"ATRASADO","MUITO ATRASADO")))) -> EM DIAS | L46: 46177 | M46: =TODAY()-L46 -> -6 | N46: =IF(M46<8,"VERIFICADO",IF(M46<15,"VERIFICAR","VERIFICAR URGENTE")) -> VERIFICADO
A47: ANA VICTORIA GOMES DE JESUS | B47: EDILEUSA CHAVES | C47: =L47 -> 46161 | D47: 46125 | E47: 47858 | F47: =(E47-D47)/7 -> 247.57143 | G47: =(TODAY()-D47)/7 -> 6.5714286 | H47: 240 | I47: 9 | J47: =IFERROR(((G47*H47)/F47)-I47,"") -> -2.6295441 | K47: =IF(J41<-10,"MUITO ADIANTADO",IF(J41<-6,"ADIANTADO",IF(J41<6,"EM DIAS",IF(J41<12,"ATRASADO","MUITO ATRASADO")))) -> EM DIAS | L47: 46161 | M47: =TODAY()-L47 -> 10 | N47: =IF(M47<8,"VERIFICADO",IF(M47<15,"VERIFICAR","VERIFICAR URGENTE")) -> VERIFICAR
A48: JÚLIO CESAR BROTA DOS SANTOS | B48: JORGE SOUZA | C48: =L48 -> 46162 | D48: 46113 | E48: 46315 | F48: =(E48-D48)/7 -> 28.857143 | G48: =(TODAY()-D48)/7 -> 8.2857143 | H48: 48 | I48: 6 | J48: =IFERROR(((G48*H48)/F48)-I48,"") -> 7.7821782 | K48: =IF(J48<-10,"MUITO ADIANTADO",IF(J48<-6,"ADIANTADO",IF(J48<6,"EM DIAS",IF(J48<12,"ATRASADO","MUITO ATRASADO")))) -> ATRASADO | L48: 46162 | M48: =TODAY()-L48 -> 9 | N48: =IF(M48<8,"VERIFICADO",IF(M48<15,"VERIFICAR","VERIFICAR URGENTE")) -> VERIFICAR
A49: ANDERSON SANTOS DOS REIS | B49: NUBIA CARVALHO | C49: =L49 -> 46162 | D49: 46111 | E49: 46770 | F49: =(E49-D49)/7 -> 94.142857 | G49: =(TODAY()-D49)/7 -> 8.5714286 | H49: 112 | I49: 2 | J49: =IFERROR(((G49*H49)/F49)-I49,"") -> 8.1972686 | K49: =IF(J49<-10,"MUITO ADIANTADO",IF(J49<-6,"ADIANTADO",IF(J49<6,"EM DIAS",IF(J49<12,"ATRASADO","MUITO ATRASADO")))) -> ATRASADO | L49: 46162 | M49: =TODAY()-L49 -> 9 | N49: =IF(M49<8,"VERIFICADO",IF(M49<15,"VERIFICAR","VERIFICAR URGENTE")) -> VERIFICAR
A50: ANDRE FARIA POSSA | B50: EDMUNDO SANTOS | C50: =L50 -> 46160 | D50: 46104 | E50: 46614 | F50: =(E50-D50)/7 -> 72.857143 | G50: =(TODAY()-D50)/7 -> 9.5714286 | H50: 48 | I50: 2 | J50: =IFERROR(((G50*H50)/F50)-I50,"") -> 4.3058824 | K50: =IF(J50<-10,"MUITO ADIANTADO",IF(J50<-6,"ADIANTADO",IF(J50<6,"EM DIAS",IF(J50<12,"ATRASADO","MUITO ATRASADO")))) -> EM DIAS | L50: 46160 | M50: =TODAY()-L50 -> 11 | N50: =IF(M50<8,"VERIFICADO",IF(M50<15,"VERIFICAR","VERIFICAR URGENTE")) -> VERIFICAR
A51: GUILHERME BARBOSA DOS SANTOS | B51: JORGE SOUZA | C51: =L51 -> 46162 | D51: 45536 | E51: 46290 | F51: =(E51-D51)/7 -> 107.71429 | G51: =(TODAY()-D51)/7 -> 90.714286 | H51: 112 | I51: 88 | J51: =IFERROR(((G51*H51)/F51)-I51,"") -> 6.3236074 | K51: =IF(J51<-10,"MUITO ADIANTADO",IF(J51<-6,"ADIANTADO",IF(J51<6,"EM DIAS",IF(J51<12,"ATRASADO","MUITO ATRASADO")))) -> ATRASADO | L51: 46162 | M51: =TODAY()-L51 -> 9 | N51: =IF(M51<8,"VERIFICADO",IF(M51<15,"VERIFICAR","VERIFICAR URGENTE")) -> VERIFICAR
A52: ANIELLI ALVES SANTOS | B52: EDILEUSA CHAVES | C52: =L52 -> 46161 | D52: 46147 | E52: 47413 | F52: =(E52-D52)/7 -> 180.85714 | G52: =(TODAY()-D52)/7 -> 3.4285714 | H52: 160 | I52: 4 | J52: =IFERROR(((G52*H52)/F52)-I52,"") -> -0.96682464 | K52: =IF(J52<-10,"MUITO ADIANTADO",IF(J52<-6,"ADIANTADO",IF(J52<6,"EM DIAS",IF(J52<12,"ATRASADO","MUITO ATRASADO")))) -> EM DIAS | L52: 46161 | M52: =TODAY()-L52 -> 10 | N52: =IF(M52<8,"VERIFICADO",IF(M52<15,"VERIFICAR","VERIFICAR URGENTE")) -> VERIFICAR
A53: ANNA JULIA DA SILVA MAGALHÃES | B53: EDILEUSA CHAVES | C53: =L53 -> 46161 | D53: 45755 | E53: 47519 | F53: =(E53-D53)/7 -> 252 | G53: =(TODAY()-D53)/7 -> 59.428571 | H53: 272 | I53: 76 | J53: =IFERROR(((G53*H53)/F53)-I53,"") -> -11.854875 | K53: =IF(J53<-10,"MUITO ADIANTADO",IF(J53<-6,"ADIANTADO",IF(J53<6,"EM DIAS",IF(J53<12,"ATRASADO","MUITO ATRASADO")))) -> MUITO ADIANTADO | L53: 46161 | M53: =TODAY()-L53 -> 10 | N53: =IF(M53<8,"VERIFICADO",IF(M53<15,"VERIFICAR","VERIFICAR URGENTE")) -> VERIFICAR
A54: LAINNA DA SILVA DE JESUS | B54: EDMUNDO SANTOS | C54: =L54 -> 46161 | D54: 45696 | E54: 46933 | F54: =(E54-D54)/7 -> 176.71429 | G54: =(TODAY()-D54)/7 -> 67.857143 | H54: 160 | I54: 58 | J54: =IFERROR(((G54*H54)/F54)-I54,"") -> 3.4389652 | K54: =IF(J54<-10,"MUITO ADIANTADO",IF(J54<-6,"ADIANTADO",IF(J54<6,"EM DIAS",IF(J54<12,"ATRASADO","MUITO ATRASADO")))) -> EM DIAS | L54: 46161 | M54: =TODAY()-L54 -> 10 | N54: =IF(M54<8,"VERIFICADO",IF(M54<15,"VERIFICAR","VERIFICAR URGENTE")) -> VERIFICAR
A55: ANTÔNIO VILTON DE SOUZA | B55: JOICE LOPES | C55: =L55 -> 46162 | D55: 45623 | E55: 46863 | F55: =(E55-D55)/7 -> 177.14286 | G55: =(TODAY()-D55)/7 -> 78.285714 | H55: 160 | I55: 78 | J55: =IFERROR(((G55*H55)/F55)-I55,"") -> -7.2903226 | K55: =IF(J55<-10,"MUITO ADIANTADO",IF(J55<-6,"ADIANTADO",IF(J55<6,"EM DIAS",IF(J55<12,"ATRASADO","MUITO ATRASADO")))) -> ADIANTADO | L55: 46162 | M55: =TODAY()-L55 -> 9 | N55: =IF(M55<8,"VERIFICADO",IF(M55<15,"VERIFICAR","VERIFICAR URGENTE")) -> VERIFICAR
A56: ARTHUR CARVALHO GONÇALVES | B56: EDILEUSA CHAVES | C56: =L56 -> 46162 | D56: 46043 | E56: 46747 | F56: =(E56-D56)/7 -> 100.57143 | G56: =(TODAY()-D56)/7 -> 18.285714 | H56: 112 | I56: 21 | J56: =IFERROR(((G56*H56)/F56)-I56,"") -> -0.63636364 | K56: =IF(J56<-10,"MUITO ADIANTADO",IF(J56<-6,"ADIANTADO",IF(J56<6,"EM DIAS",IF(J56<12,"ATRASADO","MUITO ATRASADO")))) -> EM DIAS | L56: 46162 | M56: =TODAY()-L56 -> 9 | N56: =IF(M56<8,"VERIFICADO",IF(M56<15,"VERIFICAR","VERIFICAR URGENTE")) -> VERIFICAR
A57: LAISLA ALICE JESUS DE OLIVEIRA | B57: EDILEUSA CHAVES | C57: =L57 -> 46161 | D57: 45664 | E57: 46218 | F57: =(E57-D57)/7 -> 79.142857 | G57: =(TODAY()-D57)/7 -> 72.428571 | H57: 92 | I57: 81 | J57: =IFERROR(((G57*H57)/F57)-I57,"") -> 3.1949458 | K57: =IF(J57<-10,"MUITO ADIANTADO",IF(J57<-6,"ADIANTADO",IF(J57<6,"EM DIAS",IF(J57<12,"ATRASADO","MUITO ATRASADO")))) -> EM DIAS | L57: 46161 | M57: =TODAY()-L57 -> 10 | N57: =IF(M57<8,"VERIFICADO",IF(M57<15,"VERIFICAR","VERIFICAR URGENTE")) -> VERIFICAR
A58: ARTHUR RONALDO MARTINS MIRANDA | B58: EDMUNDO SANTOS | C58: =L58 -> 46163 | D58: 45733 | E58: 46325 | F58: =(E58-D58)/7 -> 84.571429 | G58: =(TODAY()-D58)/7 -> 62.571429 | H58: 80 | I58: 53 | J58: =IFERROR(((G58*H58)/F58)-I58,"") -> 6.1891892 | K58: =IF(J58<-10,"MUITO ADIANTADO",IF(J58<-6,"ADIANTADO",IF(J58<6,"EM DIAS",IF(J58<12,"ATRASADO","MUITO ATRASADO")))) -> ATRASADO | L58: 46163 | M58: =TODAY()-L58 -> 8 | N58: =IF(M58<8,"VERIFICADO",IF(M58<15,"VERIFICAR","VERIFICAR URGENTE")) -> VERIFICAR
A59: AYSHALA EMANUELE DA SILVA SANTOS | B59: EDILEUSA CHAVES | C59: =L59 -> 46161 | D59: 46140 | E59: 46676 | F59: =(E59-D59)/7 -> 76.571429 | G59: =(TODAY()-D59)/7 -> 4.4285714 | H59: 80 | I59: 5 | J59: =IFERROR(((G59*H59)/F59)-I59,"") -> -0.37313433 | K59: =IF(J59<-10,"MUITO ADIANTADO",IF(J59<-6,"ADIANTADO",IF(J59<6,"EM DIAS",IF(J59<12,"ATRASADO","MUITO ATRASADO")))) -> EM DIAS | L59: 46161 | M59: =TODAY()-L59 -> 10 | N59: =IF(M59<8,"VERIFICADO",IF(M59<15,"VERIFICAR","VERIFICAR URGENTE")) -> VERIFICAR
... A108: DHEISON NASCIMENTO DE OLIVEIRA | B108: EDMUNDO SANTOS | C108: =L108 -> 46162 | D108: 45931 | E108: 46478 | F108: =(E108-D108)/7 -> 78.142857 | G108: =(TODAY()-D108)/7 -> 34.285714 | H108: 80 | I108: 37 | J108: =IFERROR(((G108*H108)/F108)-I108,"") -> -1.8994516 | K108: =IF(J108<-10,"MUITO ADIANTADO",IF(J108<-6,"ADIANTADO",IF(J108<6,"EM DIAS",IF(J108<12,"ATRASADO","MUITO ATRASADO")))) -> EM DIAS | L108: 46162 | M108: =TODAY()-L108 -> 9 | N108: =IF(M108<8,"VERIFICADO",IF(M108<15,"VERIFICAR","VERIFICAR URGENTE")) -> VERIFICAR
A109: DHENEFY HELOISE DOS SANTOS GOMES | B109: EDMUNDO SANTOS | C109: =L109 -> 46158 | D109: 46135 | E109: 46798 | F109: =(E109-D109)/7 -> 94.714286 | G109: 0 | H109: 96 | I109: 4 | J109: =IFERROR(((G109*H109)/F109)-I109,"") -> -4 | K109: =IF(J109<-10,"MUITO ADIANTADO",IF(J109<-6,"ADIANTADO",IF(J109<6,"EM DIAS",IF(J109<12,"ATRASADO","MUITO ATRASADO")))) -> EM DIAS | L109: 46158 | M109: =TODAY()-L109 -> 13 | N109: =IF(M109<8,"VERIFICADO",IF(M109<15,"VERIFICAR","VERIFICAR URGENTE")) -> VERIFICAR
...

Sheet CENTRO
A2: DATA ATUAL | B2: =TODAY() -> 46171 | C2: =TODAY() -> 46171 | O2: DIEF
A3: ALUNO | B3: DIA DO CURSO | C3: DATA INICIO | D3: DATA TERMINO | E3: TOTAL DE SEMANAS | F3: TOTAL DE SEMANAS CONCLUIDAS | G3: AULAS DO CURSO | H3: AULAS CONCLUIDAS | I3: % AULAS CONCLUIDAS | J3: % DIAS CONCLUIDOS | K3: AULAS ATRASADAS | L3: SITUAÇÃO | M3: DATA DO ACOMPA. | N3: DIAS VERIFICADO | O3: STATUS | P3: RENOVAÇÕES | T3: SITUAÇÃO DO ACOMPANHAMENTO | U3: FICHA PREENCHIDA
A4: SARA PEREIRA DA SILVA | B4: =M4 -> 45453 | C4: 45215 | D4: 45776 | E4: =(D4-C4)/7 -> 80.142857 | F4: =($B$2-C4)/7 -> 136.57143 | G4: 80 | H4: 26 | K4: =IFERROR(((F4*G4)/E4)-H4,"") -> 110.32799 | L4: =IF(K4<-10,"MUITO ADIANTADO",IF(K4<-6,"ADIANTADO",IF(K4<6,"EM DIAS",IF(K4<12,"ATRASADO","MUITO ATRASADO")))) -> MUITO ATRASADO | M4: 45453 | N4: =$B$2-M4 -> 718 | O4: =IF(N4<8,"VERIFICADO",IF(N4<15,"VERIFICAR","VERIFICAR URGENTE")) -> VERIFICAR URGENTE
A5: ADRIELLY DO CARMO SANTOS | B5: =M5 -> 45450 | C5: 45331 | D5: 45478 | E5: =(D5-C5)/7 -> 21 | F5: =($B$2-C5)/7 -> 120 | G5: 16 | H5: 9 | K5: =IFERROR(((F5*G5)/E5)-H5,"") -> 82.428571 | L5: =IF(K5<-10,"MUITO ADIANTADO",IF(K5<-6,"ADIANTADO",IF(K5<6,"EM DIAS",IF(K5<12,"ATRASADO","MUITO ATRASADO")))) -> MUITO ATRASADO | M5: 45450 | N5: =$B$2-M5 -> 721 | O5: =IF(N5<8,"VERIFICADO",IF(N5<15,"VERIFICAR","VERIFICAR URGENTE")) -> VERIFICAR URGENTE
A6: CARLOS DANIEL SILVA CRUZ | B6: =M6 -> 45449 | C6: 45008 | D6: 45491 | E6: =(D6-C6)/7 -> 69 | F6: =($B$2-C6)/7 -> 166.14286 | G6: 80 | H6: 68 | K6: =IFERROR(((F6*G6)/E6)-H6,"") -> 124.6294 | L6: =IF(K6<-10,"MUITO ADIANTADO",IF(K6<-6,"ADIANTADO",IF(K6<6,"EM DIAS",IF(K6<12,"ATRASADO","MUITO ATRASADO")))) -> MUITO ATRASADO | M6: 45449 | N6: =$B$2-M6 -> 722 | O6: =IF(N6<8,"VERIFICADO",IF(N6<15,"VERIFICAR","VERIFICAR URGENTE")) -> VERIFICAR URGENTE
A7: ALANA ARAUJO COSTA | B7: =M7 -> 45454 | C7: 44778 | D7: 46027 | E7: =(D7-C7)/7 -> 178.42857 | F7: =($B$2-C7)/7 -> 199 | G7: 269 | H7: 112 | I7: =IFERROR(H7/G7,"") -> 0.41635688 | J7: =IFERROR(F7/E7,"") -> 1.1152922 | K7: =IFERROR(((F7*G7)/E7)-H7,"") -> 188.01361 | L7: =IF(K7<-10,"MUITO ADIANTADO",IF(K7<-6,"ADIANTADO",IF(K7<6,"EM DIAS",IF(K7<12,"ATRASADO","MUITO ATRASADO")))) -> MUITO ATRASADO | M7: 45454 | N7: =$B$2-M7 -> 717 | O7: =IF(N7<8,"VERIFICADO",IF(N7<15,"VERIFICAR","VERIFICAR URGENTE")) -> VERIFICAR URGENTE
A8: ALESSANDRO OLIVEIRA DA SILVA | B8: =M8 -> 45451 | C8: 45391 | D8: 45757 | E8: =(D8-C8)/7 -> 52.285714 | F8: =($B$2-C8)/7 -> 111.42857 | G8: 48 | H8: 1 | K8: =IFERROR(((F8*G8)/E8)-H8,"") -> 101.29508 | L8: =IF(K8<-10,"MUITO ADIANTADO",IF(K8<-6,"ADIANTADO",IF(K8<6,"EM DIAS",IF(K8<12,"ATRASADO","MUITO ATRASADO")))) -> MUITO ATRASADO | M8: 45451 | N8: =$B$2-M8 -> 720 | O8: =IF(N8<8,"VERIFICADO",IF(N8<15,"VERIFICAR","VERIFICAR URGENTE")) -> VERIFICAR URGENTE
A9: CAIO DOS SANTOS FERREIRA | B9: =M9 -> 45451 | C9: 44912 | D9: 45493 | E9: =(D9-C9)/7 -> 83 | F9: =($B$2-C9)/7 -> 179.85714 | G9: 177 | H9: 168 | I9: =IFERROR(H9/G9,"") -> 0.94915254 | J9: =IFERROR(F9/E9,"") -> 2.1669535 | K9: =IFERROR(((F9*G9)/E9)-H9,"") -> 215.55077 | L9: =IF(K9<-10,"MUITO ADIANTADO",IF(K9<-6,"ADIANTADO",IF(K9<6,"EM DIAS",IF(K9<12,"ATRASADO","MUITO ATRASADO")))) -> MUITO ATRASADO | M9: 45451 | N9: =$B$2-M9 -> 720 | O9: =IF(N9<8,"VERIFICADO",IF(N9<15,"VERIFICAR","VERIFICAR URGENTE")) -> VERIFICAR URGENTE
A10: JONATHAS DE QUEIROZ SANTOS | B10: =M10 -> 45450 | C10: 44897 | D10: 46536 | E10: =(D10-C10)/7 -> 234.14286 | F10: =($B$2-C10)/7 -> 182 | G10: 280 | H10: 103 | I10: =IFERROR(H10/G10,"") -> 0.36785714 | J10: =IFERROR(F10/E10,"") -> 0.77730323 | K10: =IFERROR(((F10*G10)/E10)-H10,"") -> 114.64491 | L10: =IF(K10<-10,"MUITO ADIANTADO",IF(K10<-6,"ADIANTADO",IF(K10<6,"EM DIAS",IF(K10<12,"ATRASADO","MUITO ATRASADO")))) -> MUITO ATRASADO | M10: 45450 | N10: =$B$2-M10 -> 721 | O10: =IF(N10<8,"VERIFICADO",IF(N10<15,"VERIFICAR","VERIFICAR URGENTE")) -> VERIFICAR URGENTE
A11: LUIS RYAN SODRÉ COÊLHO | B11: =M11 -> 45448 | C11: 45044 | D11: 45530 | E11: =(D11-C11)/7 -> 69.428571 | F11: =($B$2-C11)/7 -> 161 | G11: 96 | H11: 86 | I11: =IFERROR(H11/G11,"") -> 0.89583333 | J11: =IFERROR(F11/E11,"") -> 2.31893 | K11: =IFERROR(((F11*G11)/E11)-H11,"") -> 136.61728 | L11: =IF(K11<-10,"MUITO ADIANTADO",IF(K11<-6,"ADIANTADO",IF(K11<6,"EM DIAS",IF(K11<12,"ATRASADO","MUITO ATRASADO")))) -> MUITO ATRASADO | M11: 45448 | N11: =$B$2-M11 -> 723 | O11: =IF(N11<8,"VERIFICADO",IF(N11<15,"VERIFICAR","VERIFICAR URGENTE")) -> VERIFICAR URGENTE
A12: MIGUEL CAMILLO PAGLIOSA | B12: =M12 -> 45450 | C12: 45134 | D12: 45562 | E12: =(D12-C12)/7 -> 61.142857 | F12: =($B$2-C12)/7 -> 148.14286 | G12: 80 | H12: 62 | I12: =IFERROR(H12/G12,"") -> 0.775 | J12: =IFERROR(F12/E12,"") -> 2.4228972 | K12: =IFERROR(((F12*G12)/E12)-H12,"") -> 131.83178 | L12: =IF(K12<-10,"MUITO ADIANTADO",IF(K12<-6,"ADIANTADO",IF(K12<6,"EM DIAS",IF(K12<12,"ATRASADO","MUITO ATRASADO")))) -> MUITO ATRASADO | M12: 45450 | N12: =$B$2-M12 -> 721 | O12: =IF(N12<8,"VERIFICADO",IF(N12<15,"VERIFICAR","VERIFICAR URGENTE")) -> VERIFICAR URGENTE
A13: ADRIAN MARQUES SANTOS | B13: =M13 -> 45453 | C13: 45246 | D13: 45741 | E13: =(D13-C13)/7 -> 70.714286 | F13: =($B$2-C13)/7 -> 132.14286 | G13: 116 | H13: 56 | I13: =IFERROR(H13/G13,"") -> 0.48275862 | J13: =IFERROR(F13/E13,"") -> 1.8686869 | K13: =IFERROR(((F13*G13)/E13)-H13,"") -> 160.76768 | L13: =IF(K13<-10,"MUITO ADIANTADO",IF(K13<-6,"ADIANTADO",IF(K13<6,"EM DIAS",IF(K13<12,"ATRASADO","MUITO ATRASADO")))) -> MUITO ATRASADO | M13: 45453 | N13: =$B$2-M13 -> 718 | O13: =IF(N13<8,"VERIFICADO",IF(N13<15,"VERIFICAR","VERIFICAR URGENTE")) -> VERIFICAR URGENTE
A14: AGHATA DA FRANÇA PEREIRA | B14: =M14 -> 45449 | C14: 45358 | D14: 46167 | E14: =(D14-C14)/7 -> 115.57143 | F14: =($B$2-C14)/7 -> 116.14286 | G14: 112 | H14: 13 | K14: =IFERROR(((F14*G14)/E14)-H14,"") -> 99.55377 | L14: =IF(K14<-10,"MUITO ADIANTADO",IF(K14<-6,"ADIANTADO",IF(K14<6,"EM DIAS",IF(K14<12,"ATRASADO","MUITO ATRASADO")))) -> MUITO ATRASADO | M14: 45449 | N14: =$B$2-M14 -> 722 | O14: =IF(N14<8,"VERIFICADO",IF(N14<15,"VERIFICAR","VERIFICAR URGENTE")) -> VERIFICAR URGENTE
A15: ALICIA VITÓRIA DE VASCONCELOS ANDRADE | B15: =M15 -> 45448 | C15: 45155 | D15: 46769 | E15: =(D15-C15)/7 -> 230.57143 | F15: =($B$2-C15)/7 -> 145.14286 | G15: 256 | H15: 44 | K15: =IFERROR(((F15*G15)/E15)-H15,"") -> 117.14994 | L15: =IF(K15<-10,"MUITO ADIANTADO",IF(K15<-6,"ADIANTADO",IF(K15<6,"EM DIAS",IF(K15<12,"ATRASADO","MUITO ATRASADO")))) -> MUITO ATRASADO | M15: 45448 | N15: =$B$2-M15 -> 723 | O15: =IF(N15<8,"VERIFICADO",IF(N15<15,"VERIFICAR","VERIFICAR URGENTE")) -> VERIFICAR URGENTE
A16: AMANDA RIBEIRO MARTINS | B16: =M16 -> 45451 | C16: 44852 | D16: 46132 | E16: =(D16-C16)/7 -> 182.85714 | F16: =($B$2-C16)/7 -> 188.42857 | G16: 253 | H16: 32 | I16: =IFERROR(H16/G16,"") -> 0.12648221 | J16: =IFERROR(F16/E16,"") -> 1.0304688 | K16: =IFERROR(((F16*G16)/E16)-H16,"") -> 228.70859 | L16: =IF(K16<-10,"MUITO ADIANTADO",IF(K16<-6,"ADIANTADO",IF(K16<6,"EM DIAS",IF(K16<12,"ATRASADO","MUITO ATRASADO")))) -> MUITO ATRASADO | M16: 45451 | N16: =$B$2-M16 -> 720 | O16: =IF(N16<8,"VERIFICADO",IF(N16<15,"VERIFICAR","VERIFICAR URGENTE")) -> VERIFICAR URGENTE
A17: CRISTINA LIMA DOS SANTOS | B17: =M17 -> 45448 | C17: 45358 | D17: 45480 | E17: =(D17-C17)/7 -> 17.428571 | F17: =($B$2-C17)/7 -> 116.14286 | G17: 16 | H17: 9 | K17: =IFERROR(((F17*G17)/E17)-H17,"") -> 97.622951 | L17: =IF(K17<-10,"MUITO ADIANTADO",IF(K17<-6,"ADIANTADO",IF(K17<6,"EM DIAS",IF(K17<12,"ATRASADO","MUITO ATRASADO")))) -> MUITO ATRASADO | M17: 45448 | N17: =$B$2-M17 -> 723 | O17: =IF(N17<8,"VERIFICADO",IF(N17<15,"VERIFICAR","VERIFICAR URGENTE")) -> VERIFICAR URGENTE
A18: DANILO DE SOUZA SANTOS | B18: =M18 -> 45451 | C18: 44681 | D18: 45333 | E18: =(D18-C18)/7 -> 93.142857 | F18: =($B$2-C18)/7 -> 212.85714 | G18: 92 | H18: 86 | I18: =IFERROR(H18/G18,"") -> 0.93478261 | J18: =IFERROR(F18/E18,"") -> 2.2852761 | K18: =IFERROR(((F18*G18)/E18)-H18,"") -> 124.2454 | L18: =IF(K18<-10,"MUITO ADIANTADO",IF(K18<-6,"ADIANTADO",IF(K18<6,"EM DIAS",IF(K18<12,"ATRASADO","MUITO ATRASADO")))) -> MUITO ATRASADO | M18: 45451 | N18: =$B$2-M18 -> 720 | O18: =IF(N18<8,"VERIFICADO",IF(N18<15,"VERIFICAR","VERIFICAR URGENTE")) -> VERIFICAR URGENTE
A19: FRANCIELEN DA SILVA BARROS | B19: =M19 -> 45449 | C19: 45358 | D19: 45907 | E19: =(D19-C19)/7 -> 78.428571 | F19: =($B$2-C19)/7 -> 116.14286 | G19: 64 | H19: 15 | K19: =IFERROR(((F19*G19)/E19)-H19,"") -> 79.775956 | L19: =IF(K19<-10,"MUITO ADIANTADO",IF(K19<-6,"ADIANTADO",IF(K19<6,"EM DIAS",IF(K19<12,"ATRASADO","MUITO ATRASADO")))) -> MUITO ATRASADO | M19: 45449 | N19: =$B$2-M19 -> 722 | O19: =IF(N19<8,"VERIFICADO",IF(N19<15,"VERIFICAR","VERIFICAR URGENTE")) -> VERIFICAR URGENTE
A20: HILLARY SILVA DOS SANTOS | B20: =M20 -> 45449 | C20: 45113 | D20: 46730 | E20: =(D20-C20)/7 -> 231 | F20: =($B$2-C20)/7 -> 151.14286 | G20: 304 | H20: 89 | I20: =IFERROR(H20/G20,"") -> 0.29276316 | J20: =IFERROR(F20/E20,"") -> 0.65429808 | K20: =IFERROR(((F20*G20)/E20)-H20,"") -> 109.90662 | L20: =IF(K20<-10,"MUITO ADIANTADO",IF(K20<-6,"ADIANTADO",IF(K20<6,"EM DIAS",IF(K20<12,"ATRASADO","MUITO ATRASADO")))) -> MUITO ATRASADO | M20: 45449 | N20: =$B$2-M20 -> 722 | O20: =IF(N20<8,"VERIFICADO",IF(N20<15,"VERIFICAR","VERIFICAR URGENTE")) -> VERIFICAR URGENTE
A21: BRUNA ETIELLE DE JESUS DARIO | B21: =M21 -> 45450 | C21: 44893 | D21: 46217 | E21: =(D21-C21)/7 -> 189.14286 | F21: =($B$2-C21)/7 -> 182.57143 | G21: 253 | H21: 64 | K21: =IFERROR(((F21*G21)/E21)-H21,"") -> 180.20997 | L21: =IF(K21<-10,"MUITO ADIANTADO",IF(K21<-6,"ADIANTADO",IF(K21<6,"EM DIAS",IF(K21<12,"ATRASADO","MUITO ATRASADO")))) -> MUITO ATRASADO | M21: 45450 | N21: =$B$2-M21 -> 721 | O21: =IF(N21<8,"VERIFICADO",IF(N21<15,"VERIFICAR","VERIFICAR URGENTE")) -> VERIFICAR URGENTE
A22: FRANCISCO DO NASCIMENTO SILVA | B22: =M22 -> 45448 | C22: 45357 | D22: 45875 | E22: =(D22-C22)/7 -> 74 | F22: =($B$2-C22)/7 -> 116.28571 | G22: 80 | H22: 10 | K22: =IFERROR(((F22*G22)/E22)-H22,"") -> 115.71429 | L22: =IF(K22<-10,"MUITO ADIANTADO",IF(K22<-6,"ADIANTADO",IF(K22<6,"EM DIAS",IF(K22<12,"ATRASADO","MUITO ATRASADO")))) -> MUITO ATRASADO | M22: 45448 | N22: =$B$2-M22 -> 723 | O22: =IF(N22<8,"VERIFICADO",IF(N22<15,"VERIFICAR","VERIFICAR URGENTE")) -> VERIFICAR URGENTE
A23: HELOISA DE MACEDO DA SILVA | B23: =M23 -> 45450 | C23: 44810 | D23: 45646 | E23: =(D23-C23)/7 -> 119.42857 | F23: =($B$2-C23)/7 -> 194.42857 | G23: 186 | H23: 92 | I23: =IFERROR(H23/G23,"") -> 0.49462366 | J23: =IFERROR(F23/E23,"") -> 1.6279904 | K23: =IFERROR(((F23*G23)/E23)-H23,"") -> 210.80622 | L23: =IF(K23<-10,"MUITO ADIANTADO",IF(K23<-6,"ADIANTADO",IF(K23<6,"EM DIAS",IF(K23<12,"ATRASADO","MUITO ATRASADO")))) -> MUITO ATRASADO | M23: 45450 | N23: =$B$2-M23 -> 721 | O23: =IF(N23<8,"VERIFICADO",IF(N23<15,"VERIFICAR","VERIFICAR URGENTE")) -> VERIFICAR URGENTE
A24: IRIS MILENA RODRIGUES DOS SANTOS | B24: =M24 -> 45449 | C24: 45056 | D24: 46701 | E24: =(D24-C24)/7 -> 235 | F24: =($B$2-C24)/7 -> 159.28571 | G24: 257 | H24: 58 | I24: =IFERROR(H24/G24,"") -> 0.22568093 | J24: =IFERROR(F24/E24,"") -> 0.67781155 | K24: =IFERROR(((F24*G24)/E24)-H24,"") -> 116.19757 | L24: =IF(K24<-10,"MUITO ADIANTADO",IF(K24<-6,"ADIANTADO",IF(K24<6,"EM DIAS",IF(K24<12,"ATRASADO","MUITO ATRASADO")))) -> MUITO ATRASADO | M24: 45449 | N24: =$B$2-M24 -> 722 | O24: =IF(N24<8,"VERIFICADO",IF(N24<15,"VERIFICAR","VERIFICAR URGENTE")) -> VERIFICAR URGENTE
A25: ANDRÉ LUCAS DA ROCHA LOPES | B25: =M25 -> 45446 | C25: 45356 | D25: 45411 | E25: =(D25-C25)/7 -> 7.8571429 | F25: =($B$2-C25)/7 -> 116.42857 | G25: 16 | H25: 5 | K25: =IFERROR(((F25*G25)/E25)-H25,"") -> 232.09091 | L25: =IF(K25<-10,"MUITO ADIANTADO",IF(K25<-6,"ADIANTADO",IF(K25<6,"EM DIAS",IF(K25<12,"ATRASADO","MUITO ATRASADO")))) -> MUITO ATRASADO | M25: 45446 | N25: =$B$2-M25 -> 725 | O25: =IF(N25<8,"VERIFICADO",IF(N25<15,"VERIFICAR","VERIFICAR URGENTE")) -> VERIFICAR URGENTE
A26: JÚLIO ALVES MARTINS | B26: =M26 -> 45447 | C26: 45081 | D26: 46701 | E26: =(D26-C26)/7 -> 231.42857 | F26: =($B$2-C26)/7 -> 155.71429 | G26: 272 | H26: 45 | I26: =IFERROR(H26/G26,"") -> 0.16544118 | J26: =IFERROR(F26/E26,"") -> 0.67283951 | K26: =IFERROR(((F26*G26)/E26)-H26,"") -> 138.01235 | L26: =IF(K26<-10,"MUITO ADIANTADO",IF(K26<-6,"ADIANTADO",IF(K26<6,"EM DIAS",IF(K26<12,"ATRASADO","MUITO ATRASADO")))) -> MUITO ATRASADO | M26: 45447 | N26: =$B$2-M26 -> 724 | O26: =IF(N26<8,"VERIFICADO",IF(N26<15,"VERIFICAR","VERIFICAR URGENTE")) -> VERIFICAR URGENTE
A27: AMANDA ANTUNES PALMEIRA | B27: =M27 -> 45453 | C27: 45411 | D27: 46096 | E27: =(D27-C27)/7 -> 97.857143 | F27: =($B$2-C27)/7 -> 108.57143 | G27: 192 | H27: 16 | I27: =IFERROR(H27/G27,"") -> 0.083333333 | J27: =IFERROR(F27/E27,"") -> 1.1094891 | K27: =IFERROR(((F27*G27)/E27)-H27,"") -> 197.0219 | L27: =IF(K27<-10,"MUITO ADIANTADO",IF(K27<-6,"ADIANTADO",IF(K27<6,"EM DIAS",IF(K27<12,"ATRASADO","MUITO ATRASADO")))) -> MUITO ATRASADO | M27: 45453 | N27: =$B$2-M27 -> 718 | O27: =IF(N27<8,"VERIFICADO",IF(N27<15,"VERIFICAR","VERIFICAR URGENTE")) -> VERIFICAR URGENTE
A28: ANA JULIA DE SOUZA SANTANA | B28: =M28 -> 45453 | C28: 45243 | D28: 45760 | E28: =(D28-C28)/7 -> 73.857143 | F28: =($B$2-C28)/7 -> 132.57143 | G28: 80 | H28: 30 | K28: =IFERROR(((F28*G28)/E28)-H28,"") -> 113.59768 | L28: =IF(K28<-10,"MUITO ADIANTADO",IF(K28<-6,"ADIANTADO",IF(K28<6,"EM DIAS",IF(K28<12,"ATRASADO","MUITO ATRASADO")))) -> MUITO ATRASADO | M28: 45453 | N28: =$B$2-M28 -> 718 | O28: =IF(N28<8,"VERIFICADO",IF(N28<15,"VERIFICAR","VERIFICAR URGENTE")) -> VERIFICAR URGENTE
A29: ANA JÚLIA OLIVEIRA SANTOS | B29: =M29 -> 45453 | C29: 44791 | D29: 45519 | E29: =(D29-C29)/7 -> 104 | F29: =($B$2-C29)/7 -> 197.14286 | G29: 74 | H29: 65 | I29: =IFERROR(H29/G29,"") -> 0.87837838 | J29: =IFERROR(F29/E29,"") -> 1.8956044 | K29: =IFERROR(((F29*G29)/E29)-H29,"") -> 75.274725 | L29: =IF(K29<-10,"MUITO ADIANTADO",IF(K29<-6,"ADIANTADO",IF(K29<6,"EM DIAS",IF(K29<12,"ATRASADO","MUITO ATRASADO")))) -> MUITO ATRASADO | M29: 45453 | N29: =$B$2-M29 -> 718 | O29: =IF(N29<8,"VERIFICADO",IF(N29<15,"VERIFICAR","VERIFICAR URGENTE")) -> VERIFICAR URGENTE
A30: ANA LUIZA RIBEIRO DISCONZI | B30: =M30 -> 45453 | C30: 45355 | D30: 45873 | E30: =(D30-C30)/7 -> 74 | F30: =($B$2-C30)/7 -> 116.57143 | G30: 80 | H30: 9 | K30: =IFERROR(((F30*G30)/E30)-H30,"") -> 117.02317 | L30: =IF(K30<-10,"MUITO ADIANTADO",IF(K30<-6,"ADIANTADO",IF(K30<6,"EM DIAS",IF(K30<12,"ATRASADO","MUITO ATRASADO")))) -> MUITO ATRASADO | M30: 45453 | N30: =$B$2-M30 -> 718 | O30: =IF(N30<8,"VERIFICADO",IF(N30<15,"VERIFICAR","VERIFICAR URGENTE")) -> VERIFICAR URGENTE
A31: ANTÔNIA AUDIRENE ALVES VIANA | B31: =M31 -> 45453 | C31: 45323 | D31: 45474 | E31: =(D31-C31)/7 -> 21.571429 | F31: =($B$2-C31)/7 -> 121.14286 | G31: 16 | H31: 8 | K31: =IFERROR(((F31*G31)/E31)-H31,"") -> 81.854305 | L31: =IF(K31<-10,"MUITO ADIANTADO",IF(K31<-6,"ADIANTADO",IF(K31<6,"EM DIAS",IF(K31<12,"ATRASADO","MUITO ATRASADO")))) -> MUITO ATRASADO | M31: 45453 | N31: =$B$2-M31 -> 718 | O31: =IF(N31<8,"VERIFICADO",IF(N31<15,"VERIFICAR","VERIFICAR URGENTE")) -> VERIFICAR URGENTE
A32: BEATRIZ MAGALHÃES DOS SANTOS | B32: =M32 -> 45453 | C32: 45075 | D32: 46689 | E32: =(D32-C32)/7 -> 230.57143 | F32: =($B$2-C32)/7 -> 156.57143 | G32: 272 | H32: 64 | I32: =IFERROR(H32/G32,"") -> 0.23529412 | J32: =IFERROR(F32/E32,"") -> 0.67905824 | K32: =IFERROR(((F32*G32)/E32)-H32,"") -> 120.70384 | L32: =IF(K32<-10,"MUITO ADIANTADO",IF(K32<-6,"ADIANTADO",IF(K32<6,"EM DIAS",IF(K32<12,"ATRASADO","MUITO ATRASADO")))) -> MUITO ATRASADO | M32: 45453 | N32: =$B$2-M32 -> 718 | O32: =IF(N32<8,"VERIFICADO",IF(N32<15,"VERIFICAR","VERIFICAR URGENTE")) -> VERIFICAR URGENTE
A33: BORIS ALECSANDER MAKOWICH FILHO | B33: =M33 -> 45453 | C33: 45137 | D33: 45794 | E33: =(D33-C33)/7 -> 93.857143 | F33: =($B$2-C33)/7 -> 147.71429 | G33: 132 | H33: 57 | I33: =IFERROR(H33/G33,"") -> 0.43181818 | J33: =IFERROR(F33/E33,"") -> 1.5738204 | K33: =IFERROR(((F33*G33)/E33)-H33,"") -> 150.74429 | L33: =IF(K33<-10,"MUITO ADIANTADO",IF(K33<-6,"ADIANTADO",IF(K33<6,"EM DIAS",IF(K33<12,"ATRASADO","MUITO ATRASADO")))) -> MUITO ATRASADO | M33: 45453 | N33: =$B$2-M33 -> 718 | O33: =IF(N33<8,"VERIFICADO",IF(N33<15,"VERIFICAR","VERIFICAR URGENTE")) -> VERIFICAR URGENTE
A34: BRUNO REIS DOS SANTOS | B34: =M34 -> 45453 | C34: 44935 | D34: 46218 | E34: =(D34-C34)/7 -> 183.28571 | F34: =($B$2-C34)/7 -> 176.57143 | G34: 253 | H34: 83 | I34: =IFERROR(H34/G34,"") -> 0.32806324 | J34: =IFERROR(F34/E34,"") -> 0.96336711 | K34: =IFERROR(((F34*G34)/E34)-H34,"") -> 160.73188 | L34: =IF(K34<-10,"MUITO ADIANTADO",IF(K34<-6,"ADIANTADO",IF(K34<6,"EM DIAS",IF(K34<12,"ATRASADO","MUITO ATRASADO")))) -> MUITO ATRASADO | M34: 45453 | N34: =$B$2-M34 -> 718 | O34: =IF(N34<8,"VERIFICADO",IF(N34<15,"VERIFICAR","VERIFICAR URGENTE")) -> VERIFICAR URGENTE
A35: CAMILA PRISCILA DE JESUS AZEVEDO | B35: =M35 -> 45453 | C35: 45173 | D35: 45862 | E35: =(D35-C35)/7 -> 98.428571 | F35: =($B$2-C35)/7 -> 142.57143 | G35: 112 | H35: 45 | I35: =IFERROR(H35/G35,"") -> 0.40178571 | J35: =IFERROR(F35/E35,"") -> 1.4484761 | K35: =IFERROR(((F35*G35)/E35)-H35,"") -> 117.22932 | L35: =IF(K35<-10,"MUITO ADIANTADO",IF(K35<-6,"ADIANTADO",IF(K35<6,"EM DIAS",IF(K35<12,"ATRASADO","MUITO ATRASADO")))) -> MUITO ATRASADO | M35: 45453 | N35: =$B$2-M35 -> 718 | O35: =IF(N35<8,"VERIFICADO",IF(N35<15,"VERIFICAR","VERIFICAR URGENTE")) -> VERIFICAR URGENTE
A36: CERFFI DREYK PEREIRA DA SILVA | B36: =M36 -> 45453 | C36: 45066 | D36: 46681 | E36: =(D36-C36)/7 -> 230.71429 | F36: =($B$2-C36)/7 -> 157.85714 | G36: 272 | H36: 60 | I36: =IFERROR(H36/G36,"") -> 0.22058824 | J36: =IFERROR(F36/E36,"") -> 0.68421053 | K36: =IFERROR(((F36*G36)/E36)-H36,"") -> 126.10526 | L36: =IF(K36<-10,"MUITO ADIANTADO",IF(K36<-6,"ADIANTADO",IF(K36<6,"EM DIAS",IF(K36<12,"ATRASADO","MUITO ATRASADO")))) -> MUITO ATRASADO | M36: 45453 | N36: =$B$2-M36 -> 718 | O36: =IF(N36<8,"VERIFICADO",IF(N36<15,"VERIFICAR","VERIFICAR URGENTE")) -> VERIFICAR URGENTE
A37: ENZO VICTOR SANTOS MACEDO | B37: =M37 -> 45450 | C37: 44915 | D37: 46193 | E37: =(D37-C37)/7 -> 182.57143 | F37: =($B$2-C37)/7 -> 179.42857 | G37: 253 | H37: 56 | I37: =IFERROR(H37/G37,"") -> 0.22134387 | J37: =IFERROR(F37/E37,"") -> 0.9827856 | K37: =IFERROR(((F37*G37)/E37)-H37,"") -> 192.64476 | L37: =IF(K37<-10,"MUITO ADIANTADO",IF(K37<-6,"ADIANTADO",IF(K37<6,"EM DIAS",IF(K37<12,"ATRASADO","MUITO ATRASADO")))) -> MUITO ATRASADO | M37: 45450 | N37: =$B$2-M37 -> 721 | O37: =IF(N37<8,"VERIFICADO",IF(N37<15,"VERIFICAR","VERIFICAR URGENTE")) -> VERIFICAR URGENTE
A38: ERICK ANDRE PEREIRA DA SILVA | B38: =M38 -> 45453 | C38: 44900 | D38: 45356 | E38: =(D38-C38)/7 -> 65.142857 | F38: =($B$2-C38)/7 -> 181.57143 | G38: 76 | H38: 70 | I38: =IFERROR(H38/G38,"") -> 0.92105263 | J38: =IFERROR(F38/E38,"") -> 2.7872807 | K38: =IFERROR(((F38*G38)/E38)-H38,"") -> 141.83333 | L38: =IF(K38<-10,"MUITO ADIANTADO",IF(K38<-6,"ADIANTADO",IF(K38<6,"EM DIAS",IF(K38<12,"ATRASADO","MUITO ATRASADO")))) -> MUITO ATRASADO | M38: 45453 | N38: =$B$2-M38 -> 718 | O38: =IF(N38<8,"VERIFICADO",IF(N38<15,"VERIFICAR","VERIFICAR URGENTE")) -> VERIFICAR URGENTE
A39: FIUK EMANUEL ALVES LIMA | B39: =M39 -> 45454 | C39: 45187 | D39: 45708 | E39: =(D39-C39)/7 -> 74.428571 | F39: =($B$2-C39)/7 -> 140.57143 | G39: 80 | H39: 30 | K39: =IFERROR(((F39*G39)/E39)-H39,"") -> 121.09405 | L39: =IF(K39<-10,"MUITO ADIANTADO",IF(K39<-6,"ADIANTADO",IF(K39<6,"EM DIAS",IF(K39<12,"ATRASADO","MUITO ATRASADO")))) -> MUITO ATRASADO | M39: 45454 | N39: =$B$2-M39 -> 717 | O39: =IF(N39<8,"VERIFICADO",IF(N39<15,"VERIFICAR","VERIFICAR URGENTE")) -> VERIFICAR URGENTE
A40: GABRIEL HENRIQUE HOFF | B40: =M40 -> 45453 | C40: 45341 | D40: 45857 | E40: =(D40-C40)/7 -> 73.714286 | F40: =($B$2-C40)/7 -> 118.57143 | G40: 80 | H40: 19 | K40: =IFERROR(((F40*G40)/E40)-H40,"") -> 109.68217 | L40: =IF(K40<-10,"MUITO ADIANTADO",IF(K40<-6,"ADIANTADO",IF(K40<6,"EM DIAS",IF(K40<12,"ATRASADO","MUITO ATRASADO")))) -> MUITO ATRASADO | M40: 45453 | N40: =$B$2-M40 -> 718 | O40: =IF(N40<8,"VERIFICADO",IF(N40<15,"VERIFICAR","VERIFICAR URGENTE")) -> VERIFICAR URGENTE
A41: GABRIELLA FERREIRA REIS | B41: =M41 -> 45454 | C41: 45197 | D41: 46376 | E41: =(D41-C41)/7 -> 168.42857 | F41: =($B$2-C41)/7 -> 139.14286 | G41: 212 | H41: 21 | K41: =IFERROR(((F41*G41)/E41)-H41,"") -> 154.13825 | L41: =IF(K41<-10,"MUITO ADIANTADO",IF(K41<-6,"ADIANTADO",IF(K41<6,"EM DIAS",IF(K41<12,"ATRASADO","MUITO ATRASADO")))) -> MUITO ATRASADO | M41: 45454 | N41: =$B$2-M41 -> 717 | O41: =IF(N41<8,"VERIFICADO",IF(N41<15,"VERIFICAR","VERIFICAR URGENTE")) -> VERIFICAR URGENTE
...

Sheet Pedido de Apostilas Centro
A2: Aluno | B2: Situação | C2: Aulas | D2: Pedir | E2: Módulo para pedido | F2: Unidade | G2: Módulo Atual / Observação
A3: MARCOS HENRIQUE ALMEIDA DA SILVA | B3: =IFERROR(VLOOKUP(A3,CENTRO!$A$4:$L$548,12,0),"") -> MUITO ATRASADO | C3: =IFERROR(VLOOKUP(A3,CENTRO!$A$4:$L$137,11,0),"") | D3: =TRUE() -> 1 | E3: MONTAGEM E MANUTENÇÃO DE HADWER | G3: MATERIAL NO ARMARIO 30/01/24
A4: MARIA CLARA SILVA DE OLIVEIRA | D4: =TRUE() -> 1 | E4: INTERNET COM OUTLOOK 2021 | G4: MATERIAL NO ARMARIO 30/01/24
A5: HILLARY SILVA DOS SANTOS | D5: =TRUE() -> 1 | E5: EMPREENDEDORISMO/ ASS ADM I | G5: MATERIAL NO ARMARIO 30/01/24
A6: NATIELLE BISPO D OLIVEIRA | D6: =TRUE() -> 1 | E6: EXCEL | G6: MATERIAL NO ARMARIO 30/01/24
A7: KARINE APARECIDA DE ARAÚJO ANTONIO | D7: =TRUE() -> 1 | E7: EXCEL 2021 | G7: MATERIAL NO ARMARIO 30/01/24
A8: LUIS RYAN SODRÉ COÊLHO | B8: =IFERROR(VLOOKUP(A8,CENTRO!$A$4:$L$548,12,0),"") -> MUITO ATRASADO | C8: =IFERROR(VLOOKUP(A8,CENTRO!$A$4:$L$548,11,0),"") -> 136.61728 | D8: =TRUE() -> 1 | E8: GOOGLE E REDES SOCIAIS | G8: MATERIAL NO ARMARIO 16/03
A9: EMANUELLY JESUS DA SILVA | B9: =IFERROR(VLOOKUP(A9,CENTRO!$A$4:$L$548,12,0),"") -> MUITO ATRASADO | C9: =IFERROR(VLOOKUP(A9,CENTRO!$A$4:$L$548,11,0),"") -> 118.16815 | D9: =TRUE() -> 1 | E9: LIDERANÇA/ ASS ADM I | G9: MATERIAL NO ARMARIO 18/04
A10: DIOGO LEITE CARVALHO | B10: =IFERROR(VLOOKUP(A10,CENTRO!$A$4:$L$548,12,0),"") | C10: =IFERROR(VLOOKUP(A10,CENTRO!$A$4:$L$548,11,0),"") | D10: =TRUE() -> 1 | E10: MOINTAGEM E MANUTENÇÃO DE H | G10: MATERIAL NO ARMARIO 29/09
A11: GESSICA SANTOS DE SOUZA | D11: =TRUE() -> 1 | E11: WORD 2021 | G11: MATERIAL NO ARMARIO 06/10
A12: ISABELLA JESUS CARVALHO DA SILVA | D12: =TRUE() -> 1 | E12: EXCEL | G12: MATERIAL NO ARMARIO 06/10
A13: ISRAEL MOTA DE JESUS | D13: =TRUE() -> TRUE | E13: SEGURANÇA NA ERA DIGITAL | G13: MATERIAL NO ARMARIO 16/02
A14: IURE DE OLIVEIRA ALVES | D14: =TRUE() -> TRUE | E14: WORD 2021 | G14: MATERIAL NO ARMARIO 16/03
A15: BRUNA ETIELLE | D15: =TRUE() -> TRUE | E15: ASSISTENTE ADM I | G15: MATERIAL NO ARMARIO 16/03
A16: LUCAS ALMEIDA BARBOSA | B16: =IFERROR(VLOOKUP(A16,CENTRO!$A$4:$L$548,12,0),"") -> MUITO ATRASADO | C16: =IFERROR(VLOOKUP(A16,CENTRO!$A$4:$L$137,11,0),"") -> 176.24034 | D16: =TRUE() -> TRUE | E16: INTERNET COM OUTLOOK 2021/ MONTAGEM | G16: MATERIAL NO ARMARIO 16/02
A17: SAMUEL RODRIGUES DA SILVA | B17: =IFERROR(VLOOKUP(A17,CENTRO!$A$4:$L$548,12,0),"") -> MUITO ATRASADO | C17: =IFERROR(VLOOKUP(A17,CENTRO!$A$4:$L$137,11,0),"") -> 185.94991 | D17: =TRUE() -> TRUE | E17: OPERADOR DE CAIXA/ ASS DE ADM FINANCEIRA | G17: MATERIAL NO ARMARIO 17/04
A18: KELY VITÓRIA SANTOS EVANGELISTA | B18: =IFERROR(VLOOKUP(A18,CENTRO!$A$4:$L$548,12,0),"") -> MUITO ATRASADO | C18: =IFERROR(VLOOKUP(A18,CENTRO!$A$4:$L$137,11,0),"") -> 186.10633 | D18: =TRUE() -> TRUE | G18: MATERIAL NO ARMARIO 16/02
A19: JOÃO VITOR SILVA MACÊDO | D19: =TRUE() -> TRUE | E19: PREMIERE/PHOTO SHOP ESSENCIAL | G19: ALUNO ACELERADO
A20: ÂNGELA DA CRUZ DE JESUS | D20: =TRUE() -> TRUE | E20: WINDOWS 11 | G20: ALUNA NOVA
A21: EVELY DA CRUZ DE JESUS | D21: =TRUE() -> TRUE | E21: WINDOWS 11 | G21: aluna nova
A22: ADRIELY DE SOUZA PEREIRA | D22: =TRUE() -> TRUE | E22: WINDOWS 11 | G22: ALUNO NOVO
A23: IASMIM BROTA DOS SANTOS | D23: =TRUE() -> TRUE | E23: WINDOWS 11 | G23: ALUNA NOVA
A24: ANA VITORIA GOMES DE SOUZA | D24: =TRUE() -> TRUE | E24: WINDOWS 11 | G24: ALUNA NOVA
A25: CAPA CARNÊ | D25: =TRUE() -> TRUE | E25: CAPA CARNÊ | G25: CAPA CARNe
A26: VITORIA PAIVA GOMES | D26: =TRUE() -> TRUE | E26: WINDOWS 11 | G26: ALUNO NOVO
A27: MATEUS PAIVA DA SILVA | D27: =TRUE() -> TRUE | E27: WINDOWS 11 | G27: ALUNO NOVO
A28: SARA CRISTINA RODRIGUES SCHIST | D28: =TRUE() -> TRUE | E28: ASSISTENTE ADM I | G28: ALUNA NOVA
A29: SABRINA SANTOS MARTINS | D29: =TRUE() -> TRUE | E29: WINDOWS 11 | G29: ALUNA NOVA
A30: DAVI DOURADO DA CRUZ SILVA | D30: =TRUE() -> 1 | E30: MONTAGEM E MANUTENÇÃO DE HANDEWARE | G30: ALUNO NOVO
... A38: BORIS ALECSANDER MAKOWICH FILHO | D38: =TRUE() -> TRUE | E38: SEGURANÇA NA ERA DIGITAL | G38: MATERIAL NO ARMARIO 22/04
A39: ANA LUIZA RIBEIRO DISCONZI | D39: =FALSE() -> 0 | E39: WINDOWS 11 | G39: MATERIAL NO ARMARIO 22/04
A40: CARLA KARINE DE LIMA SANTOS | D40: =FALSE() -> 0 | E40: WORD 2021 | G40: MATERIAL NO ARMARIO 22/04
A41: ANDRÉ LUCAS DA ROCHA LOPES | D41: =FALSE() -> 0 | E41: ASSITENTE ADM I | G41: MATERIAL NO ARMARIO 22/04
A42: CAMILA DE ARAUJO ROCHA | D42: =FALSE() -> 0 | E42: WORD 2021 | G42: MATERIAL NO ARMARIO 22/04
A43: CRISTINA LIMA DOS SANTOS | D43: =FALSE() -> 0 | E43: WINDOWS 11 | G43: MATERIAL NO ARMARIO 22/04
A44: FRANCISCO DO NASCIMENTO SILVA | D44: =FALSE() -> 0 | E44: WINDOWS 11 | G44: MATERIAL NO ARMARIO 22/04
A45: AGHATA DA FRANÇA PEREIRA | D45: =FALSE() -> 0 | E45: WINDOWS 11 | G45: MATERIAL NO ARMARIO 22/04
A46: FRANCIELEN DA SILVA BARROS | D46: =FALSE() -> 0 | E46: WORD 2021 | G46: MATERIAL NO ARMARIO 22/04
A47: LAURA OLIVEIRA DOS SANTOS | D47: =FALSE() -> 0 | E47: WINDOWS 11 | G47: MATERIAL NO ARMARIO 22/04
A48: YASMIN DOS SANTOS DE SOUZA | D48: =FALSE() -> 0 | E48: WINDOWS 11 | G48: MATERIAL NO ARMARIO 22/04
...
